<?xml version="1.0"?>
<robot xmlns:xacro="http://www.ros.org/wiki/xacro"  name="robot">
    <xacro:include filename="inertial_macros.xacro"/>
    
<!--BASE FOOTPRINT LINK-->
    <link name="base_footprint">
        
    </link>

<!--BASE LINK-->
    <link name="base_link">
        <visual name="">
            <origin xyz="0.0 0.0 0.1" rpy="0.0 0.0 0.0"/>
            <geometry>
                <box size="0.4 0.3 0.2"/>
            </geometry>
            <material name="">
                <color rgba="1.0 0.0 0.0 1.0"/>
            </material>
        </visual>
        <collision>
            <origin xyz="0.0 0.0 0.1" rpy="0.0 0.0 0.0"/>
            <geometry>
                <box size="0.4 0.3 0.2"/>
            </geometry>
        </collision>
        <xacro:inertial_box mass = "0.05" x = "0.4" y = "0.3" z = "0.2">
            <origin xyz="0.0 0.0 0.1" rpy="0.0 0.0 0.0"/>
            
        </xacro:inertial_box>
    </link>
    <gazebo reference="base_link">
        <material>Gazebo/Red</material>
    </gazebo>

<!--LEFT WHEEL FRONT LINK-->
    <link name="left_wheel_front">
        <visual name="">
            <origin xyz="0.0 0.0 0.0" rpy="0.0 0.0 0.0"/>
            <geometry>
                <cylinder radius="0.07" length="0.04"/>
            </geometry>
            <material name="">
                <color rgba="1.0 1.0 1.0 1.0"/>
            </material>
        </visual>
        <collision>
            <origin xyz="0.0 0.0 0.0" rpy="0.0 0.0 0.0"/>
            <geometry>
                <cylinder radius="0.07" length="0.04"/>
            </geometry>
        </collision>
        <xacro:inertial_cylinder mass = "0.01" length = "0.04" radius = "0.07">
            <origin xyz="0 0 0" rpy="0.0 0.0 0.0"/>
            
        </xacro:inertial_cylinder>
        
    </link>
    <gazebo reference="left_wheel_front">
        <material>Gazebo/White</material>
    </gazebo>

<!--LEFT WHEEL BACK LINK-->
    <link name="left_wheel_back">
        <visual name="">
            <origin xyz="0.0 0.0 0.0" rpy="0.0 0.0 0.0"/>
            <geometry>
                <cylinder radius="0.07" length="0.04"/>
            </geometry>
            <material name="">
                <color rgba="1.0 1.0 1.0 1.0"/>
            </material>
        </visual>
        <collision>
            <origin xyz="0.0 0.0 0.0" rpy="0.0 0.0 0.0"/>
            <geometry>
                <cylinder radius="0.07" length="0.04"/>
            </geometry>
        </collision>
        <xacro:inertial_cylinder mass = "0.01" length = "0.04" radius = "0.07">
            <origin xyz="0 0 0" rpy="0.0 0.0 0.0"/>
            
        </xacro:inertial_cylinder>
        
    </link>
    <gazebo reference="left_wheel_back">
        <material>Gazebo/White</material>
    </gazebo>

<!--RIGHT WHEEL FRONT LINK-->
    <link name="right_wheel_front">
        <visual name="">
            <origin xyz="0.0 0.0 0.0" rpy="0.0 0.0 0.0"/>
            <geometry>
                <cylinder radius="0.07" length="0.04"/>
            </geometry>
            <material name="">
                <color rgba="1.0 1.0 1.0 1.0"/>
            </material>
        </visual>
        <collision>
            <origin xyz="0.0 0.0 0.0" rpy="0.0 0.0 0.0"/>
            <geometry>
                <cylinder radius="0.07" length="0.04"/>
            </geometry>
        </collision>
        <xacro:inertial_cylinder mass = "0.01" length = "0.04" radius = "0.07">
            <origin xyz="0 0 0" rpy="0.0 0.0 0.0"/>
        </xacro:inertial_cylinder>
        
    </link>
    <gazebo reference="right_wheel_front">
        <material>Gazebo/White</material>
    </gazebo>

<!--RIGHT WHEEL BACK LINK-->
    <link name="right_wheel_back">
        <visual name="">
            <origin xyz="0.0 0.0 0.0" rpy="0.0 0.0 0.0"/>
            <geometry>
                <cylinder radius="0.07" length="0.04"/>
            </geometry>
            <material name="">
                <color rgba="1.0 1.0 1.0 1.0"/>
            </material>
        </visual>
        <collision>
            <origin xyz="0.0 0.0 0.0" rpy="0.0 0.0 0.0"/>
            <geometry>
                <cylinder radius="0.07" length="0.04"/>
            </geometry>
        </collision>
        <xacro:inertial_cylinder mass = "0.01" length = "0.04" radius = "0.07">
            <origin xyz="0 0 0" rpy="0.0 0.0 0.0"/>
            
        </xacro:inertial_cylinder>

        
    </link>
    <gazebo reference="right_wheel_back">
        <material>Gazebo/White</material>
    </gazebo>

<!--BASE-FOOTPRINT TO BASE LINK JOINT-->
    <joint name="base_footprint" type="fixed">
        <origin xyz="0.0 0.0 0.07" rpy="0.0 0.0 0.0"/>
        <parent link="base_footprint"/>
        <child link="base_link"/>
    </joint>

<!--BASE LINK TO LEFT WHEEL FRONT JOINT-->
    <joint name="left_wheel_front_joint" type="continuous">
        <origin xyz="0.1 0.17 0.0" rpy="${pi/2} 0.0 0.0"/>
        <parent link="base_link"/>
        <child link="left_wheel_front"/>
        <axis xyz="0.0 0.0 -1.0"/>
        <limit lower="0.0" upper="0.0" effort="0.0" velocity="0.0"/>
    </joint>

<!--BASE LINK TO LEFT WHEEL BACK JOINT-->
    <joint name="left_wheel_back_joint" type="continuous">
        <origin xyz="-0.1 0.17 0.0" rpy="${pi/2} 0.0 0.0"/>
        <parent link="base_link"/>
        <child link="left_wheel_back"/>
        <axis xyz="0.0 0.0 -1.0"/>
        <limit lower="0.0" upper="0.0" effort="0.0" velocity="0.0"/>
    </joint>

<!--BASE LINK TO RIGHT WHEEL FRONT JOINT-->
    <joint name="right_wheel_front_joint" type="continuous">
        <origin xyz="0.1 -0.17 0.0" rpy="${pi/2} 0.0 0.0"/>
        <parent link="base_link"/>
        <child link="right_wheel_front"/>
        <axis xyz="0.0 0.0 -1.0"/>
    </joint>

<!--BASE LINK TO RIGHT WHEEL BACK JOINT-->
    <joint name="right_wheel_back_joint" type="continuous">
        <origin xyz="-0.1 -0.17 0.0" rpy="${pi/2} 0.0 0.0"/>
        <parent link="base_link"/>
        <child link="right_wheel_back"/>
        <axis xyz="0.0 0.0 -1.0"/>
    </joint>


</robot>